Workbook
Name Cfg_Units: Config!$B$2
Name Cfg_StartWeight: Config!$B$6
Name Cfg_StartDate: Config!$B$7
Name Cfg_GoalWeight: Config!$B$8
Name Cfg_TDEE: Config!$B$14
Name Cfg_TargetDeficit: Config!$B$15
Name Cfg_FatConstant: Config!$B$18
Name DL_Date: 'Daily Log'!$A$2:$A$1001
Name DL_Weight: 'Daily Log'!$B$2:$B$1001
Name WL_Date: 'Workout Log'!$A$2:$A$5001
Name WL_Exercise: 'Workout Log'!$B$2:$B$5001
Name WL_Set: 'Workout Log'!$C$2:$C$5001
Name WL_Reps: 'Workout Log'!$D$2:$D$5001
Name WL_Weight: 'Workout Log'!$E$2:$E$5001
Name WL_RPE: 'Workout Log'!$F$2:$F$5001
Name WL_Volume: 'Workout Log'!$H$2:$H$5001
Name WL_e1RM: 'Workout Log'!$I$2:$I$5001
Name Lib_Exercise: 'Exercise Library'!$A$2:$A$201

Sheet README
A1: Fitness Tracker — Setup & Usage
A3: STEP 1 — Upload this .xlsx to Google Drive, then open it and choose
A4: File → Save as Google Sheets. Work from the Sheets version.
A6: STEP 2 — Fill in the Config tab (units, starting weight, goal, height,
A7: age, sex, activity level, target deficit). Everything else
A8: reads from Config — do not hardcode values anywhere else.
A10: STEP 3 — Point the Telegram (Hermes) agent at the two append schemas
A11: below. The agent should append one row per logged event.
A13: APPEND SCHEMAS (column order matters):
A15: Daily Log:
A16: Date | Weight | Kcal In | Kcal Burned (exercise) | <leave rest blank>
A17: The remaining columns (Net Kcal, Cumulative Deficit, Theoretical Fat
... A42: Divergence column shows the gap.

Sheet Config
A1: Setting | B1: Value | C1: Notes
A2: Units | B2: lbs/in | C2: Type 'lbs/in' or 'kg/cm'
A3: Sex | B3: M | C3: 'M' or 'F' (Mifflin-St Jeor)
A4: Age | B4: 30 | C4: years
A5: Height | B5: 70 | C5: inches if lbs/in, cm if kg/cm
A6: Starting Weight | B6: 200 | C6: lbs or kg, per Units
A7: Starting Date | B7: 46156 | C7: first day you're tracking
A8: Goal Weight | B8: 175 | C8: lbs or kg
A9: Activity Level | B9: Moderate | C9: Sedentary / Light / Moderate / Active / Very Active
A10: Activity Multiplier | B10: =IFERROR(VLOOKUP(B9,{"Sedentary",1.2;"Light",1.375;"Moderate",1.55;"Active",1.725;"Very Active",1.9},2,FALSE),1.55) | C10: auto from Activity Level
A11: Weight (kg) | B11: =IF(B2="kg/cm",B6,B6/2.2046226218) | C11: auto
A12: Height (cm) | B12: =IF(B2="kg/cm",B5,B5*2.54) | C12: auto
A13: BMR (kcal/day) | B13: =IF(B3="M",10*B11+6.25*B12-5*B4+5,10*B11+6.25*B12-5*B4-161) | C13: Mifflin-St Jeor
A14: TDEE (kcal/day) | B14: =B13*B10 | C14: BMR × activity
A15: Target Daily Deficit | B15: 500 | C15: kcal below TDEE
A16: Kcal per lb fat | B16: 3500 | C16: constant
A17: Kcal per kg fat | B17: 7700 | C17: constant
A18: Fat constant (active) | B18: =IF(B2="kg/cm",B17,B16) | C18: auto

Sheet Daily Log
A1: Date | B1: Weight | C1: Kcal In | D1: Kcal Burned | E1: Net Kcal | F1: Cumulative Deficit | G1: Theoretical Fat Lost | H1: Theoretical Weight | I1: Actual Δ | J1: Divergence | K1: 7-day Avg Weight | L1: Notes
E2: =IF(C2="","",C2-Cfg_TDEE-IFERROR(D2,0)) | F2: =IF(E2="","",-E2) | G2: =IF(F2="","",F2/Cfg_FatConstant) | H2: =IF(G2="","",Cfg_StartWeight-G2) | I2: =IF(B2="","",Cfg_StartWeight-B2) | J2: =IF(OR(B2="",G2=""),"",I2-G2) | K2: =IF(B2="","",IFERROR(AVERAGEIFS($B$2:$B$1001,$A$2:$A$1001,">="&A2-6,$A$2:$A$1001,"<="&A2),""))
E3: =IF(C3="","",C3-Cfg_TDEE-IFERROR(D3,0)) | F3: =IF(E3="","",IFERROR(F2,0)+(-E3)) | G3: =IF(F3="","",F3/Cfg_FatConstant) | H3: =IF(G3="","",Cfg_StartWeight-G3) | I3: =IF(B3="","",Cfg_StartWeight-B3) | J3: =IF(OR(B3="",G3=""),"",I3-G3) | K3: =IF(B3="","",IFERROR(AVERAGEIFS($B$2:$B$1001,$A$2:$A$1001,">="&A3-6,$A$2:$A$1001,"<="&A3),""))
E4: =IF(C4="","",C4-Cfg_TDEE-IFERROR(D4,0)) | F4: =IF(E4="","",IFERROR(F3,0)+(-E4)) | G4: =IF(F4="","",F4/Cfg_FatConstant) | H4: =IF(G4="","",Cfg_StartWeight-G4) | I4: =IF(B4="","",Cfg_StartWeight-B4) | J4: =IF(OR(B4="",G4=""),"",I4-G4) | K4: =IF(B4="","",IFERROR(AVERAGEIFS($B$2:$B$1001,$A$2:$A$1001,">="&A4-6,$A$2:$A$1001,"<="&A4),""))
E5: =IF(C5="","",C5-Cfg_TDEE-IFERROR(D5,0)) | F5: =IF(E5="","",IFERROR(F4,0)+(-E5)) | G5: =IF(F5="","",F5/Cfg_FatConstant) | H5: =IF(G5="","",Cfg_StartWeight-G5) | I5: =IF(B5="","",Cfg_StartWeight-B5) | J5: =IF(OR(B5="",G5=""),"",I5-G5) | K5: =IF(B5="","",IFERROR(AVERAGEIFS($B$2:$B$1001,$A$2:$A$1001,">="&A5-6,$A$2:$A$1001,"<="&A5),""))
E6: =IF(C6="","",C6-Cfg_TDEE-IFERROR(D6,0)) | F6: =IF(E6="","",IFERROR(F5,0)+(-E6)) | G6: =IF(F6="","",F6/Cfg_FatConstant) | H6: =IF(G6="","",Cfg_StartWeight-G6) | I6: =IF(B6="","",Cfg_StartWeight-B6) | J6: =IF(OR(B6="",G6=""),"",I6-G6) | K6: =IF(B6="","",IFERROR(AVERAGEIFS($B$2:$B$1001,$A$2:$A$1001,">="&A6-6,$A$2:$A$1001,"<="&A6),""))
E7: =IF(C7="","",C7-Cfg_TDEE-IFERROR(D7,0)) | F7: =IF(E7="","",IFERROR(F6,0)+(-E7)) | G7: =IF(F7="","",F7/Cfg_FatConstant) | H7: =IF(G7="","",Cfg_StartWeight-G7) | I7: =IF(B7="","",Cfg_StartWeight-B7) | J7: =IF(OR(B7="",G7=""),"",I7-G7) | K7: =IF(B7="","",IFERROR(AVERAGEIFS($B$2:$B$1001,$A$2:$A$1001,">="&A7-6,$A$2:$A$1001,"<="&A7),""))
E8: =IF(C8="","",C8-Cfg_TDEE-IFERROR(D8,0)) | F8: =IF(E8="","",IFERROR(F7,0)+(-E8)) | G8: =IF(F8="","",F8/Cfg_FatConstant) | H8: =IF(G8="","",Cfg_StartWeight-G8) | I8: =IF(B8="","",Cfg_StartWeight-B8) | J8: =IF(OR(B8="",G8=""),"",I8-G8) | K8: =IF(B8="","",IFERROR(AVERAGEIFS($B$2:$B$1001,$A$2:$A$1001,">="&A8-6,$A$2:$A$1001,"<="&A8),""))
E9: =IF(C9="","",C9-Cfg_TDEE-IFERROR(D9,0)) | F9: =IF(E9="","",IFERROR(F8,0)+(-E9)) | G9: =IF(F9="","",F9/Cfg_FatConstant) | H9: =IF(G9="","",Cfg_StartWeight-G9) | I9: =IF(B9="","",Cfg_StartWeight-B9) | J9: =IF(OR(B9="",G9=""),"",I9-G9) | K9: =IF(B9="","",IFERROR(AVERAGEIFS($B$2:$B$1001,$A$2:$A$1001,">="&A9-6,$A$2:$A$1001,"<="&A9),""))
E10: =IF(C10="","",C10-Cfg_TDEE-IFERROR(D10,0)) | F10: =IF(E10="","",IFERROR(F9,0)+(-E10)) | G10: =IF(F10="","",F10/Cfg_FatConstant) | H10: =IF(G10="","",Cfg_StartWeight-G10) | I10: =IF(B10="","",Cfg_StartWeight-B10) | J10: =IF(OR(B10="",G10=""),"",I10-G10) | K10: =IF(B10="","",IFERROR(AVERAGEIFS($B$2:$B$1001,$A$2:$A$1001,">="&A10-6,$A$2:$A$1001,"<="&A10),""))
E11: =IF(C11="","",C11-Cfg_TDEE-IFERROR(D11,0)) | F11: =IF(E11="","",IFERROR(F10,0)+(-E11)) | G11: =IF(F11="","",F11/Cfg_FatConstant) | H11: =IF(G11="","",Cfg_StartWeight-G11) | I11: =IF(B11="","",Cfg_StartWeight-B11) | J11: =IF(OR(B11="",G11=""),"",I11-G11) | K11: =IF(B11="","",IFERROR(AVERAGEIFS($B$2:$B$1001,$A$2:$A$1001,">="&A11-6,$A$2:$A$1001,"<="&A11),""))
E12: =IF(C12="","",C12-Cfg_TDEE-IFERROR(D12,0)) | F12: =IF(E12="","",IFERROR(F11,0)+(-E12)) | G12: =IF(F12="","",F12/Cfg_FatConstant) | H12: =IF(G12="","",Cfg_StartWeight-G12) | I12: =IF(B12="","",Cfg_StartWeight-B12) | J12: =IF(OR(B12="",G12=""),"",I12-G12) | K12: =IF(B12="","",IFERROR(AVERAGEIFS($B$2:$B$1001,$A$2:$A$1001,">="&A12-6,$A$2:$A$1001,"<="&A12),""))
E13: =IF(C13="","",C13-Cfg_TDEE-IFERROR(D13,0)) | F13: =IF(E13="","",IFERROR(F12,0)+(-E13)) | G13: =IF(F13="","",F13/Cfg_FatConstant) | H13: =IF(G13="","",Cfg_StartWeight-G13) | I13: =IF(B13="","",Cfg_StartWeight-B13) | J13: =IF(OR(B13="",G13=""),"",I13-G13) | K13: =IF(B13="","",IFERROR(AVERAGEIFS($B$2:$B$1001,$A$2:$A$1001,">="&A13-6,$A$2:$A$1001,"<="&A13),""))
E14: =IF(C14="","",C14-Cfg_TDEE-IFERROR(D14,0)) | F14: =IF(E14="","",IFERROR(F13,0)+(-E14)) | G14: =IF(F14="","",F14/Cfg_FatConstant) | H14: =IF(G14="","",Cfg_StartWeight-G14) | I14: =IF(B14="","",Cfg_StartWeight-B14) | J14: =IF(OR(B14="",G14=""),"",I14-G14) | K14: =IF(B14="","",IFERROR(AVERAGEIFS($B$2:$B$1001,$A$2:$A$1001,">="&A14-6,$A$2:$A$1001,"<="&A14),""))
... E1001: =IF(C1001="","",C1001-Cfg_TDEE-IFERROR(D1001,0)) | F1001: =IF(E1001="","",IFERROR(F1000,0)+(-E1001)) | G1001: =IF(F1001="","",F1001/Cfg_FatConstant) | H1001: =IF(G1001="","",Cfg_StartWeight-G1001) | I1001: =IF(B1001="","",Cfg_StartWeight-B1001) | J1001: =IF(OR(B1001="",G1001=""),"",I1001-G1001) | K1001: =IF(B1001="","",IFERROR(AVERAGEIFS($B$2:$B$1001,$A$2:$A$1001,">="&A1001-6,$A$2:$A$1001,"<="&A1001),""))

Sheet Workout Log
A1: Date | B1: Exercise | C1: Set | D1: Reps | E1: Weight | F1: RPE | G1: Notes | H1: Volume | I1: e1RM | J1: Is PR
H2: =IF(OR(D2="",E2=""),"",D2*E2) | I2: =IF(OR(D2="",E2=""),"",E2*(1+D2/30)) | J2: =IF(I2="","",IF(I2>=MAXIFS($I$2:$I$5001,$B$2:$B$5001,B2,$A$2:$A$5001,"<="&A2),"PR",""))
H3: =IF(OR(D3="",E3=""),"",D3*E3) | I3: =IF(OR(D3="",E3=""),"",E3*(1+D3/30)) | J3: =IF(I3="","",IF(I3>=MAXIFS($I$2:$I$5001,$B$2:$B$5001,B3,$A$2:$A$5001,"<="&A3),"PR",""))
H4: =IF(OR(D4="",E4=""),"",D4*E4) | I4: =IF(OR(D4="",E4=""),"",E4*(1+D4/30)) | J4: =IF(I4="","",IF(I4>=MAXIFS($I$2:$I$5001,$B$2:$B$5001,B4,$A$2:$A$5001,"<="&A4),"PR",""))
H5: =IF(OR(D5="",E5=""),"",D5*E5) | I5: =IF(OR(D5="",E5=""),"",E5*(1+D5/30)) | J5: =IF(I5="","",IF(I5>=MAXIFS($I$2:$I$5001,$B$2:$B$5001,B5,$A$2:$A$5001,"<="&A5),"PR",""))
H6: =IF(OR(D6="",E6=""),"",D6*E6) | I6: =IF(OR(D6="",E6=""),"",E6*(1+D6/30)) | J6: =IF(I6="","",IF(I6>=MAXIFS($I$2:$I$5001,$B$2:$B$5001,B6,$A$2:$A$5001,"<="&A6),"PR",""))
H7: =IF(OR(D7="",E7=""),"",D7*E7) | I7: =IF(OR(D7="",E7=""),"",E7*(1+D7/30)) | J7: =IF(I7="","",IF(I7>=MAXIFS($I$2:$I$5001,$B$2:$B$5001,B7,$A$2:$A$5001,"<="&A7),"PR",""))
H8: =IF(OR(D8="",E8=""),"",D8*E8) | I8: =IF(OR(D8="",E8=""),"",E8*(1+D8/30)) | J8: =IF(I8="","",IF(I8>=MAXIFS($I$2:$I$5001,$B$2:$B$5001,B8,$A$2:$A$5001,"<="&A8),"PR",""))
H9: =IF(OR(D9="",E9=""),"",D9*E9) | I9: =IF(OR(D9="",E9=""),"",E9*(1+D9/30)) | J9: =IF(I9="","",IF(I9>=MAXIFS($I$2:$I$5001,$B$2:$B$5001,B9,$A$2:$A$5001,"<="&A9),"PR",""))
H10: =IF(OR(D10="",E10=""),"",D10*E10) | I10: =IF(OR(D10="",E10=""),"",E10*(1+D10/30)) | J10: =IF(I10="","",IF(I10>=MAXIFS($I$2:$I$5001,$B$2:$B$5001,B10,$A$2:$A$5001,"<="&A10),"PR",""))
H11: =IF(OR(D11="",E11=""),"",D11*E11) | I11: =IF(OR(D11="",E11=""),"",E11*(1+D11/30)) | J11: =IF(I11="","",IF(I11>=MAXIFS($I$2:$I$5001,$B$2:$B$5001,B11,$A$2:$A$5001,"<="&A11),"PR",""))
H12: =IF(OR(D12="",E12=""),"",D12*E12) | I12: =IF(OR(D12="",E12=""),"",E12*(1+D12/30)) | J12: =IF(I12="","",IF(I12>=MAXIFS($I$2:$I$5001,$B$2:$B$5001,B12,$A$2:$A$5001,"<="&A12),"PR",""))
H13: =IF(OR(D13="",E13=""),"",D13*E13) | I13: =IF(OR(D13="",E13=""),"",E13*(1+D13/30)) | J13: =IF(I13="","",IF(I13>=MAXIFS($I$2:$I$5001,$B$2:$B$5001,B13,$A$2:$A$5001,"<="&A13),"PR",""))
... H5001: =IF(OR(D5001="",E5001=""),"",D5001*E5001) | I5001: =IF(OR(D5001="",E5001=""),"",E5001*(1+D5001/30)) | J5001: =IF(I5001="","",IF(I5001>=MAXIFS($I$2:$I$5001,$B$2:$B$5001,B5001,$A$2:$A$5001,"<="&A5001),"PR",""))

Sheet Exercise Library
A1: Exercise | B1: Category | C1: Primary Muscle | D1: Secondary | E1: Equipment | F1: Heaviest Weight | G1: Best e1RM | H1: Last Performed | I1: Last Session
A2: Back Squat | B2: Legs | C2: Quads | D2: Glutes, Hamstrings | E2: Barbell | F2: =IF(A2="","",IFERROR(MAXIFS(WL_Weight,WL_Exercise,A2),"")) | G2: =IF(A2="","",IFERROR(MAXIFS(WL_e1RM,WL_Exercise,A2),"")) | H2: =IF(A2="","",IFERROR(MAXIFS(WL_Date,WL_Exercise,A2),"")) | I2: =IF(OR(A2="",H2=""),"",IFERROR(TEXTJOIN(", ",TRUE,IF((WL_Exercise=A2)*(WL_Date=H2),WL_Reps&"×"&WL_Weight,"")),""))
A3: Front Squat | B3: Legs | C3: Quads | D3: Glutes, Core | E3: Barbell | F3: =IF(A3="","",IFERROR(MAXIFS(WL_Weight,WL_Exercise,A3),"")) | G3: =IF(A3="","",IFERROR(MAXIFS(WL_e1RM,WL_Exercise,A3),"")) | H3: =IF(A3="","",IFERROR(MAXIFS(WL_Date,WL_Exercise,A3),"")) | I3: =IF(OR(A3="",H3=""),"",IFERROR(TEXTJOIN(", ",TRUE,IF((WL_Exercise=A3)*(WL_Date=H3),WL_Reps&"×"&WL_Weight,"")),""))
A4: Deadlift | B4: Pull | C4: Posterior | D4: Back, Hamstrings | E4: Barbell | F4: =IF(A4="","",IFERROR(MAXIFS(WL_Weight,WL_Exercise,A4),"")) | G4: =IF(A4="","",IFERROR(MAXIFS(WL_e1RM,WL_Exercise,A4),"")) | H4: =IF(A4="","",IFERROR(MAXIFS(WL_Date,WL_Exercise,A4),"")) | I4: =IF(OR(A4="",H4=""),"",IFERROR(TEXTJOIN(", ",TRUE,IF((WL_Exercise=A4)*(WL_Date=H4),WL_Reps&"×"&WL_Weight,"")),""))
A5: Romanian Deadlift | B5: Pull | C5: Hamstrings | D5: Glutes, Back | E5: Barbell | F5: =IF(A5="","",IFERROR(MAXIFS(WL_Weight,WL_Exercise,A5),"")) | G5: =IF(A5="","",IFERROR(MAXIFS(WL_e1RM,WL_Exercise,A5),"")) | H5: =IF(A5="","",IFERROR(MAXIFS(WL_Date,WL_Exercise,A5),"")) | I5: =IF(OR(A5="",H5=""),"",IFERROR(TEXTJOIN(", ",TRUE,IF((WL_Exercise=A5)*(WL_Date=H5),WL_Reps&"×"&WL_Weight,"")),""))
A6: Bench Press | B6: Push | C6: Chest | D6: Triceps, Shoulders | E6: Barbell | F6: =IF(A6="","",IFERROR(MAXIFS(WL_Weight,WL_Exercise,A6),"")) | G6: =IF(A6="","",IFERROR(MAXIFS(WL_e1RM,WL_Exercise,A6),"")) | H6: =IF(A6="","",IFERROR(MAXIFS(WL_Date,WL_Exercise,A6),"")) | I6: =IF(OR(A6="",H6=""),"",IFERROR(TEXTJOIN(", ",TRUE,IF((WL_Exercise=A6)*(WL_Date=H6),WL_Reps&"×"&WL_Weight,"")),""))
A7: Incline Bench | B7: Push | C7: Upper Chest | D7: Triceps, Shoulders | E7: Barbell | F7: =IF(A7="","",IFERROR(MAXIFS(WL_Weight,WL_Exercise,A7),"")) | G7: =IF(A7="","",IFERROR(MAXIFS(WL_e1RM,WL_Exercise,A7),"")) | H7: =IF(A7="","",IFERROR(MAXIFS(WL_Date,WL_Exercise,A7),"")) | I7: =IF(OR(A7="",H7=""),"",IFERROR(TEXTJOIN(", ",TRUE,IF((WL_Exercise=A7)*(WL_Date=H7),WL_Reps&"×"&WL_Weight,"")),""))
A8: Overhead Press | B8: Push | C8: Shoulders | D8: Triceps | E8: Barbell | F8: =IF(A8="","",IFERROR(MAXIFS(WL_Weight,WL_Exercise,A8),"")) | G8: =IF(A8="","",IFERROR(MAXIFS(WL_e1RM,WL_Exercise,A8),"")) | H8: =IF(A8="","",IFERROR(MAXIFS(WL_Date,WL_Exercise,A8),"")) | I8: =IF(OR(A8="",H8=""),"",IFERROR(TEXTJOIN(", ",TRUE,IF((WL_Exercise=A8)*(WL_Date=H8),WL_Reps&"×"&WL_Weight,"")),""))
A9: Barbell Row | B9: Pull | C9: Back | D9: Biceps, Rear Delts | E9: Barbell | F9: =IF(A9="","",IFERROR(MAXIFS(WL_Weight,WL_Exercise,A9),"")) | G9: =IF(A9="","",IFERROR(MAXIFS(WL_e1RM,WL_Exercise,A9),"")) | H9: =IF(A9="","",IFERROR(MAXIFS(WL_Date,WL_Exercise,A9),"")) | I9: =IF(OR(A9="",H9=""),"",IFERROR(TEXTJOIN(", ",TRUE,IF((WL_Exercise=A9)*(WL_Date=H9),WL_Reps&"×"&WL_Weight,"")),""))
A10: Pull-Up | B10: Pull | C10: Lats | D10: Biceps, Back | E10: Bodyweight | F10: =IF(A10="","",IFERROR(MAXIFS(WL_Weight,WL_Exercise,A10),"")) | G10: =IF(A10="","",IFERROR(MAXIFS(WL_e1RM,WL_Exercise,A10),"")) | H10: =IF(A10="","",IFERROR(MAXIFS(WL_Date,WL_Exercise,A10),"")) | I10: =IF(OR(A10="",H10=""),"",IFERROR(TEXTJOIN(", ",TRUE,IF((WL_Exercise=A10)*(WL_Date=H10),WL_Reps&"×"&WL_Weight,"")),""))
A11: Chin-Up | B11: Pull | C11: Biceps | D11: Lats | E11: Bodyweight | F11: =IF(A11="","",IFERROR(MAXIFS(WL_Weight,WL_Exercise,A11),"")) | G11: =IF(A11="","",IFERROR(MAXIFS(WL_e1RM,WL_Exercise,A11),"")) | H11: =IF(A11="","",IFERROR(MAXIFS(WL_Date,WL_Exercise,A11),"")) | I11: =IF(OR(A11="",H11=""),"",IFERROR(TEXTJOIN(", ",TRUE,IF((WL_Exercise=A11)*(WL_Date=H11),WL_Reps&"×"&WL_Weight,"")),""))
A12: Dip | B12: Push | C12: Chest | D12: Triceps | E12: Bodyweight | F12: =IF(A12="","",IFERROR(MAXIFS(WL_Weight,WL_Exercise,A12),"")) | G12: =IF(A12="","",IFERROR(MAXIFS(WL_e1RM,WL_Exercise,A12),"")) | H12: =IF(A12="","",IFERROR(MAXIFS(WL_Date,WL_Exercise,A12),"")) | I12: =IF(OR(A12="",H12=""),"",IFERROR(TEXTJOIN(", ",TRUE,IF((WL_Exercise=A12)*(WL_Date=H12),WL_Reps&"×"&WL_Weight,"")),""))
A13: Push-Up | B13: Push | C13: Chest | D13: Triceps, Shoulders | E13: Bodyweight | F13: =IF(A13="","",IFERROR(MAXIFS(WL_Weight,WL_Exercise,A13),"")) | G13: =IF(A13="","",IFERROR(MAXIFS(WL_e1RM,WL_Exercise,A13),"")) | H13: =IF(A13="","",IFERROR(MAXIFS(WL_Date,WL_Exercise,A13),"")) | I13: =IF(OR(A13="",H13=""),"",IFERROR(TEXTJOIN(", ",TRUE,IF((WL_Exercise=A13)*(WL_Date=H13),WL_Reps&"×"&WL_Weight,"")),""))
... A22: DB Press | B22: Push | C22: Shoulders | D22: Triceps | E22: Dumbbell | F22: =IF(A22="","",IFERROR(MAXIFS(WL_Weight,WL_Exercise,A22),"")) | G22: =IF(A22="","",IFERROR(MAXIFS(WL_e1RM,WL_Exercise,A22),"")) | H22: =IF(A22="","",IFERROR(MAXIFS(WL_Date,WL_Exercise,A22),"")) | I22: =IF(OR(A22="",H22=""),"",IFERROR(TEXTJOIN(", ",TRUE,IF((WL_Exercise=A22)*(WL_Date=H22),WL_Reps&"×"&WL_Weight,"")),""))
A23: Lateral Raise | B23: Push | C23: Side Delts | E23: Dumbbell | F23: =IF(A23="","",IFERROR(MAXIFS(WL_Weight,WL_Exercise,A23),"")) | G23: =IF(A23="","",IFERROR(MAXIFS(WL_e1RM,WL_Exercise,A23),"")) | H23: =IF(A23="","",IFERROR(MAXIFS(WL_Date,WL_Exercise,A23),"")) | I23: =IF(OR(A23="",H23=""),"",IFERROR(TEXTJOIN(", ",TRUE,IF((WL_Exercise=A23)*(WL_Date=H23),WL_Reps&"×"&WL_Weight,"")),""))
A24: Curl | B24: Pull | C24: Biceps | D24: Forearms | E24: Dumbbell | F24: =IF(A24="","",IFERROR(MAXIFS(WL_Weight,WL_Exercise,A24),"")) | G24: =IF(A24="","",IFERROR(MAXIFS(WL_e1RM,WL_Exercise,A24),"")) | H24: =IF(A24="","",IFERROR(MAXIFS(WL_Date,WL_Exercise,A24),"")) | I24: =IF(OR(A24="",H24=""),"",IFERROR(TEXTJOIN(", ",TRUE,IF((WL_Exercise=A24)*(WL_Date=H24),WL_Reps&"×"&WL_Weight,"")),""))
A25: Tricep Extension | B25: Push | C25: Triceps | E25: Dumbbell | F25: =IF(A25="","",IFERROR(MAXIFS(WL_Weight,WL_Exercise,A25),"")) | G25: =IF(A25="","",IFERROR(MAXIFS(WL_e1RM,WL_Exercise,A25),"")) | H25: =IF(A25="","",IFERROR(MAXIFS(WL_Date,WL_Exercise,A25),"")) | I25: =IF(OR(A25="",H25=""),"",IFERROR(TEXTJOIN(", ",TRUE,IF((WL_Exercise=A25)*(WL_Date=H25),WL_Reps&"×"&WL_Weight,"")),""))
A26: Plank | B26: Core | C26: Core | E26: Bodyweight | F26: =IF(A26="","",IFERROR(MAXIFS(WL_Weight,WL_Exercise,A26),"")) | G26: =IF(A26="","",IFERROR(MAXIFS(WL_e1RM,WL_Exercise,A26),"")) | H26: =IF(A26="","",IFERROR(MAXIFS(WL_Date,WL_Exercise,A26),"")) | I26: =IF(OR(A26="",H26=""),"",IFERROR(TEXTJOIN(", ",TRUE,IF((WL_Exercise=A26)*(WL_Date=H26),WL_Reps&"×"&WL_Weight,"")),""))
A27: Hanging Leg Raise | B27: Core | C27: Abs | D27: Hip Flexors | E27: Bodyweight | F27: =IF(A27="","",IFERROR(MAXIFS(WL_Weight,WL_Exercise,A27),"")) | G27: =IF(A27="","",IFERROR(MAXIFS(WL_e1RM,WL_Exercise,A27),"")) | H27: =IF(A27="","",IFERROR(MAXIFS(WL_Date,WL_Exercise,A27),"")) | I27: =IF(OR(A27="",H27=""),"",IFERROR(TEXTJOIN(", ",TRUE,IF((WL_Exercise=A27)*(WL_Date=H27),WL_Reps&"×"&WL_Weight,"")),""))
A28: Run | B28: Cardio | C28: Legs | E28: Cardio | F28: =IF(A28="","",IFERROR(MAXIFS(WL_Weight,WL_Exercise,A28),"")) | G28: =IF(A28="","",IFERROR(MAXIFS(WL_e1RM,WL_Exercise,A28),"")) | H28: =IF(A28="","",IFERROR(MAXIFS(WL_Date,WL_Exercise,A28),"")) | I28: =IF(OR(A28="",H28=""),"",IFERROR(TEXTJOIN(", ",TRUE,IF((WL_Exercise=A28)*(WL_Date=H28),WL_Reps&"×"&WL_Weight,"")),""))
A29: Bike | B29: Cardio | C29: Legs | E29: Cardio | F29: =IF(A29="","",IFERROR(MAXIFS(WL_Weight,WL_Exercise,A29),"")) | G29: =IF(A29="","",IFERROR(MAXIFS(WL_e1RM,WL_Exercise,A29),"")) | H29: =IF(A29="","",IFERROR(MAXIFS(WL_Date,WL_Exercise,A29),"")) | I29: =IF(OR(A29="",H29=""),"",IFERROR(TEXTJOIN(", ",TRUE,IF((WL_Exercise=A29)*(WL_Date=H29),WL_Reps&"×"&WL_Weight,"")),""))
A30: Row (Erg) | B30: Cardio | C30: Full Body | E30: Cardio | F30: =IF(A30="","",IFERROR(MAXIFS(WL_Weight,WL_Exercise,A30),"")) | G30: =IF(A30="","",IFERROR(MAXIFS(WL_e1RM,WL_Exercise,A30),"")) | H30: =IF(A30="","",IFERROR(MAXIFS(WL_Date,WL_Exercise,A30),"")) | I30: =IF(OR(A30="",H30=""),"",IFERROR(TEXTJOIN(", ",TRUE,IF((WL_Exercise=A30)*(WL_Date=H30),WL_Reps&"×"&WL_Weight,"")),""))
F31: =IF(A31="","",IFERROR(MAXIFS(WL_Weight,WL_Exercise,A31),"")) | G31: =IF(A31="","",IFERROR(MAXIFS(WL_e1RM,WL_Exercise,A31),"")) | H31: =IF(A31="","",IFERROR(MAXIFS(WL_Date,WL_Exercise,A31),"")) | I31: =IF(OR(A31="",H31=""),"",IFERROR(TEXTJOIN(", ",TRUE,IF((WL_Exercise=A31)*(WL_Date=H31),WL_Reps&"×"&WL_Weight,"")),""))
F32: =IF(A32="","",IFERROR(MAXIFS(WL_Weight,WL_Exercise,A32),"")) | G32: =IF(A32="","",IFERROR(MAXIFS(WL_e1RM,WL_Exercise,A32),"")) | H32: =IF(A32="","",IFERROR(MAXIFS(WL_Date,WL_Exercise,A32),"")) | I32: =IF(OR(A32="",H32=""),"",IFERROR(TEXTJOIN(", ",TRUE,IF((WL_Exercise=A32)*(WL_Date=H32),WL_Reps&"×"&WL_Weight,"")),""))
F33: =IF(A33="","",IFERROR(MAXIFS(WL_Weight,WL_Exercise,A33),"")) | G33: =IF(A33="","",IFERROR(MAXIFS(WL_e1RM,WL_Exercise,A33),"")) | H33: =IF(A33="","",IFERROR(MAXIFS(WL_Date,WL_Exercise,A33),"")) | I33: =IF(OR(A33="",H33=""),"",IFERROR(TEXTJOIN(", ",TRUE,IF((WL_Exercise=A33)*(WL_Date=H33),WL_Reps&"×"&WL_Weight,"")),""))
F34: =IF(A34="","",IFERROR(MAXIFS(WL_Weight,WL_Exercise,A34),"")) | G34: =IF(A34="","",IFERROR(MAXIFS(WL_e1RM,WL_Exercise,A34),"")) | H34: =IF(A34="","",IFERROR(MAXIFS(WL_Date,WL_Exercise,A34),"")) | I34: =IF(OR(A34="",H34=""),"",IFERROR(TEXTJOIN(", ",TRUE,IF((WL_Exercise=A34)*(WL_Date=H34),WL_Reps&"×"&WL_Weight,"")),""))
F35: =IF(A35="","",IFERROR(MAXIFS(WL_Weight,WL_Exercise,A35),"")) | G35: =IF(A35="","",IFERROR(MAXIFS(WL_e1RM,WL_Exercise,A35),"")) | H35: =IF(A35="","",IFERROR(MAXIFS(WL_Date,WL_Exercise,A35),"")) | I35: =IF(OR(A35="",H35=""),"",IFERROR(TEXTJOIN(", ",TRUE,IF((WL_Exercise=A35)*(WL_Date=H35),WL_Reps&"×"&WL_Weight,"")),""))
F36: =IF(A36="","",IFERROR(MAXIFS(WL_Weight,WL_Exercise,A36),"")) | G36: =IF(A36="","",IFERROR(MAXIFS(WL_e1RM,WL_Exercise,A36),"")) | H36: =IF(A36="","",IFERROR(MAXIFS(WL_Date,WL_Exercise,A36),"")) | I36: =IF(OR(A36="",H36=""),"",IFERROR(TEXTJOIN(", ",TRUE,IF((WL_Exercise=A36)*(WL_Date=H36),WL_Reps&"×"&WL_Weight,"")),""))
F37: =IF(A37="","",IFERROR(MAXIFS(WL_Weight,WL_Exercise,A37),"")) | G37: =IF(A37="","",IFERROR(MAXIFS(WL_e1RM,WL_Exercise,A37),"")) | H37: =IF(A37="","",IFERROR(MAXIFS(WL_Date,WL_Exercise,A37),"")) | I37: =IF(OR(A37="",H37=""),"",IFERROR(TEXTJOIN(", ",TRUE,IF((WL_Exercise=A37)*(WL_Date=H37),WL_Reps&"×"&WL_Weight,"")),""))
F38: =IF(A38="","",IFERROR(MAXIFS(WL_Weight,WL_Exercise,A38),"")) | G38: =IF(A38="","",IFERROR(MAXIFS(WL_e1RM,WL_Exercise,A38),"")) | H38: =IF(A38="","",IFERROR(MAXIFS(WL_Date,WL_Exercise,A38),"")) | I38: =IF(OR(A38="",H38=""),"",IFERROR(TEXTJOIN(", ",TRUE,IF((WL_Exercise=A38)*(WL_Date=H38),WL_Reps&"×"&WL_Weight,"")),""))
F39: =IF(A39="","",IFERROR(MAXIFS(WL_Weight,WL_Exercise,A39),"")) | G39: =IF(A39="","",IFERROR(MAXIFS(WL_e1RM,WL_Exercise,A39),"")) | H39: =IF(A39="","",IFERROR(MAXIFS(WL_Date,WL_Exercise,A39),"")) | I39: =IF(OR(A39="",H39=""),"",IFERROR(TEXTJOIN(", ",TRUE,IF((WL_Exercise=A39)*(WL_Date=H39),WL_Reps&"×"&WL_Weight,"")),""))
F40: =IF(A40="","",IFERROR(MAXIFS(WL_Weight,WL_Exercise,A40),"")) | G40: =IF(A40="","",IFERROR(MAXIFS(WL_e1RM,WL_Exercise,A40),"")) | H40: =IF(A40="","",IFERROR(MAXIFS(WL_Date,WL_Exercise,A40),"")) | I40: =IF(OR(A40="",H40=""),"",IFERROR(TEXTJOIN(", ",TRUE,IF((WL_Exercise=A40)*(WL_Date=H40),WL_Reps&"×"&WL_Weight,"")),""))
F41: =IF(A41="","",IFERROR(MAXIFS(WL_Weight,WL_Exercise,A41),"")) | G41: =IF(A41="","",IFERROR(MAXIFS(WL_e1RM,WL_Exercise,A41),"")) | H41: =IF(A41="","",IFERROR(MAXIFS(WL_Date,WL_Exercise,A41),"")) | I41: =IF(OR(A41="",H41=""),"",IFERROR(TEXTJOIN(", ",TRUE,IF((WL_Exercise=A41)*(WL_Date=H41),WL_Reps&"×"&WL_Weight,"")),""))
F42: =IF(A42="","",IFERROR(MAXIFS(WL_Weight,WL_Exercise,A42),"")) | G42: =IF(A42="","",IFERROR(MAXIFS(WL_e1RM,WL_Exercise,A42),"")) | H42: =IF(A42="","",IFERROR(MAXIFS(WL_Date,WL_Exercise,A42),"")) | I42: =IF(OR(A42="",H42=""),"",IFERROR(TEXTJOIN(", ",TRUE,IF((WL_Exercise=A42)*(WL_Date=H42),WL_Reps&"×"&WL_Weight,"")),""))
... F201: =IF(A201="","",IFERROR(MAXIFS(WL_Weight,WL_Exercise,A201),"")) | G201: =IF(A201="","",IFERROR(MAXIFS(WL_e1RM,WL_Exercise,A201),"")) | H201: =IF(A201="","",IFERROR(MAXIFS(WL_Date,WL_Exercise,A201),"")) | I201: =IF(OR(A201="",H201=""),"",IFERROR(TEXTJOIN(", ",TRUE,IF((WL_Exercise=A201)*(WL_Date=H201),WL_Reps&"×"&WL_Weight,"")),""))

Sheet PRs
A1: Exercise | B1: Heaviest Weight | C1: Heaviest Date | D1: Best e1RM | E1: Best e1RM Date | F1: Best e1RM Reps | G1: Best e1RM Weight
A2: ='Exercise Library'!A2 | B2: =IF(A2="","",IFERROR(MAXIFS(WL_Weight,WL_Exercise,A2),"")) | C2: =IF(OR(A2="",B2=""),"",IFERROR(XLOOKUP(1,(WL_Exercise=A2)*(WL_Weight=B2),WL_Date,"",0),"")) | D2: =IF(A2="","",IFERROR(MAXIFS(WL_e1RM,WL_Exercise,A2),"")) | E2: =IF(OR(A2="",D2=""),"",IFERROR(XLOOKUP(1,(WL_Exercise=A2)*(WL_e1RM=D2),WL_Date,"",0),"")) | F2: =IF(OR(A2="",D2=""),"",IFERROR(XLOOKUP(1,(WL_Exercise=A2)*(WL_e1RM=D2),WL_Reps,"",0),"")) | G2: =IF(OR(A2="",D2=""),"",IFERROR(XLOOKUP(1,(WL_Exercise=A2)*(WL_e1RM=D2),WL_Weight,"",0),""))
A3: ='Exercise Library'!A3 | B3: =IF(A3="","",IFERROR(MAXIFS(WL_Weight,WL_Exercise,A3),"")) | C3: =IF(OR(A3="",B3=""),"",IFERROR(XLOOKUP(1,(WL_Exercise=A3)*(WL_Weight=B3),WL_Date,"",0),"")) | D3: =IF(A3="","",IFERROR(MAXIFS(WL_e1RM,WL_Exercise,A3),"")) | E3: =IF(OR(A3="",D3=""),"",IFERROR(XLOOKUP(1,(WL_Exercise=A3)*(WL_e1RM=D3),WL_Date,"",0),"")) | F3: =IF(OR(A3="",D3=""),"",IFERROR(XLOOKUP(1,(WL_Exercise=A3)*(WL_e1RM=D3),WL_Reps,"",0),"")) | G3: =IF(OR(A3="",D3=""),"",IFERROR(XLOOKUP(1,(WL_Exercise=A3)*(WL_e1RM=D3),WL_Weight,"",0),""))
A4: ='Exercise Library'!A4 | B4: =IF(A4="","",IFERROR(MAXIFS(WL_Weight,WL_Exercise,A4),"")) | C4: =IF(OR(A4="",B4=""),"",IFERROR(XLOOKUP(1,(WL_Exercise=A4)*(WL_Weight=B4),WL_Date,"",0),"")) | D4: =IF(A4="","",IFERROR(MAXIFS(WL_e1RM,WL_Exercise,A4),"")) | E4: =IF(OR(A4="",D4=""),"",IFERROR(XLOOKUP(1,(WL_Exercise=A4)*(WL_e1RM=D4),WL_Date,"",0),"")) | F4: =IF(OR(A4="",D4=""),"",IFERROR(XLOOKUP(1,(WL_Exercise=A4)*(WL_e1RM=D4),WL_Reps,"",0),"")) | G4: =IF(OR(A4="",D4=""),"",IFERROR(XLOOKUP(1,(WL_Exercise=A4)*(WL_e1RM=D4),WL_Weight,"",0),""))
A5: ='Exercise Library'!A5 | B5: =IF(A5="","",IFERROR(MAXIFS(WL_Weight,WL_Exercise,A5),"")) | C5: =IF(OR(A5="",B5=""),"",IFERROR(XLOOKUP(1,(WL_Exercise=A5)*(WL_Weight=B5),WL_Date,"",0),"")) | D5: =IF(A5="","",IFERROR(MAXIFS(WL_e1RM,WL_Exercise,A5),"")) | E5: =IF(OR(A5="",D5=""),"",IFERROR(XLOOKUP(1,(WL_Exercise=A5)*(WL_e1RM=D5),WL_Date,"",0),"")) | F5: =IF(OR(A5="",D5=""),"",IFERROR(XLOOKUP(1,(WL_Exercise=A5)*(WL_e1RM=D5),WL_Reps,"",0),"")) | G5: =IF(OR(A5="",D5=""),"",IFERROR(XLOOKUP(1,(WL_Exercise=A5)*(WL_e1RM=D5),WL_Weight,"",0),""))
A6: ='Exercise Library'!A6 | B6: =IF(A6="","",IFERROR(MAXIFS(WL_Weight,WL_Exercise,A6),"")) | C6: =IF(OR(A6="",B6=""),"",IFERROR(XLOOKUP(1,(WL_Exercise=A6)*(WL_Weight=B6),WL_Date,"",0),"")) | D6: =IF(A6="","",IFERROR(MAXIFS(WL_e1RM,WL_Exercise,A6),"")) | E6: =IF(OR(A6="",D6=""),"",IFERROR(XLOOKUP(1,(WL_Exercise=A6)*(WL_e1RM=D6),WL_Date,"",0),"")) | F6: =IF(OR(A6="",D6=""),"",IFERROR(XLOOKUP(1,(WL_Exercise=A6)*(WL_e1RM=D6),WL_Reps,"",0),"")) | G6: =IF(OR(A6="",D6=""),"",IFERROR(XLOOKUP(1,(WL_Exercise=A6)*(WL_e1RM=D6),WL_Weight,"",0),""))
A7: ='Exercise Library'!A7 | B7: =IF(A7="","",IFERROR(MAXIFS(WL_Weight,WL_Exercise,A7),"")) | C7: =IF(OR(A7="",B7=""),"",IFERROR(XLOOKUP(1,(WL_Exercise=A7)*(WL_Weight=B7),WL_Date,"",0),"")) | D7: =IF(A7="","",IFERROR(MAXIFS(WL_e1RM,WL_Exercise,A7),"")) | E7: =IF(OR(A7="",D7=""),"",IFERROR(XLOOKUP(1,(WL_Exercise=A7)*(WL_e1RM=D7),WL_Date,"",0),"")) | F7: =IF(OR(A7="",D7=""),"",IFERROR(XLOOKUP(1,(WL_Exercise=A7)*(WL_e1RM=D7),WL_Reps,"",0),"")) | G7: =IF(OR(A7="",D7=""),"",IFERROR(XLOOKUP(1,(WL_Exercise=A7)*(WL_e1RM=D7),WL_Weight,"",0),""))
A8: ='Exercise Library'!A8 | B8: =IF(A8="","",IFERROR(MAXIFS(WL_Weight,WL_Exercise,A8),"")) | C8: =IF(OR(A8="",B8=""),"",IFERROR(XLOOKUP(1,(WL_Exercise=A8)*(WL_Weight=B8),WL_Date,"",0),"")) | D8: =IF(A8="","",IFERROR(MAXIFS(WL_e1RM,WL_Exercise,A8),"")) | E8: =IF(OR(A8="",D8=""),"",IFERROR(XLOOKUP(1,(WL_Exercise=A8)*(WL_e1RM=D8),WL_Date,"",0),"")) | F8: =IF(OR(A8="",D8=""),"",IFERROR(XLOOKUP(1,(WL_Exercise=A8)*(WL_e1RM=D8),WL_Reps,"",0),"")) | G8: =IF(OR(A8="",D8=""),"",IFERROR(XLOOKUP(1,(WL_Exercise=A8)*(WL_e1RM=D8),WL_Weight,"",0),""))
A9: ='Exercise Library'!A9 | B9: =IF(A9="","",IFERROR(MAXIFS(WL_Weight,WL_Exercise,A9),"")) | C9: =IF(OR(A9="",B9=""),"",IFERROR(XLOOKUP(1,(WL_Exercise=A9)*(WL_Weight=B9),WL_Date,"",0),"")) | D9: =IF(A9="","",IFERROR(MAXIFS(WL_e1RM,WL_Exercise,A9),"")) | E9: =IF(OR(A9="",D9=""),"",IFERROR(XLOOKUP(1,(WL_Exercise=A9)*(WL_e1RM=D9),WL_Date,"",0),"")) | F9: =IF(OR(A9="",D9=""),"",IFERROR(XLOOKUP(1,(WL_Exercise=A9)*(WL_e1RM=D9),WL_Reps,"",0),"")) | G9: =IF(OR(A9="",D9=""),"",IFERROR(XLOOKUP(1,(WL_Exercise=A9)*(WL_e1RM=D9),WL_Weight,"",0),""))
A10: ='Exercise Library'!A10 | B10: =IF(A10="","",IFERROR(MAXIFS(WL_Weight,WL_Exercise,A10),"")) | C10: =IF(OR(A10="",B10=""),"",IFERROR(XLOOKUP(1,(WL_Exercise=A10)*(WL_Weight=B10),WL_Date,"",0),"")) | D10: =IF(A10="","",IFERROR(MAXIFS(WL_e1RM,WL_Exercise,A10),"")) | E10: =IF(OR(A10="",D10=""),"",IFERROR(XLOOKUP(1,(WL_Exercise=A10)*(WL_e1RM=D10),WL_Date,"",0),"")) | F10: =IF(OR(A10="",D10=""),"",IFERROR(XLOOKUP(1,(WL_Exercise=A10)*(WL_e1RM=D10),WL_Reps,"",0),"")) | G10: =IF(OR(A10="",D10=""),"",IFERROR(XLOOKUP(1,(WL_Exercise=A10)*(WL_e1RM=D10),WL_Weight,"",0),""))
A11: ='Exercise Library'!A11 | B11: =IF(A11="","",IFERROR(MAXIFS(WL_Weight,WL_Exercise,A11),"")) | C11: =IF(OR(A11="",B11=""),"",IFERROR(XLOOKUP(1,(WL_Exercise=A11)*(WL_Weight=B11),WL_Date,"",0),"")) | D11: =IF(A11="","",IFERROR(MAXIFS(WL_e1RM,WL_Exercise,A11),"")) | E11: =IF(OR(A11="",D11=""),"",IFERROR(XLOOKUP(1,(WL_Exercise=A11)*(WL_e1RM=D11),WL_Date,"",0),"")) | F11: =IF(OR(A11="",D11=""),"",IFERROR(XLOOKUP(1,(WL_Exercise=A11)*(WL_e1RM=D11),WL_Reps,"",0),"")) | G11: =IF(OR(A11="",D11=""),"",IFERROR(XLOOKUP(1,(WL_Exercise=A11)*(WL_e1RM=D11),WL_Weight,"",0),""))
A12: ='Exercise Library'!A12 | B12: =IF(A12="","",IFERROR(MAXIFS(WL_Weight,WL_Exercise,A12),"")) | C12: =IF(OR(A12="",B12=""),"",IFERROR(XLOOKUP(1,(WL_Exercise=A12)*(WL_Weight=B12),WL_Date,"",0),"")) | D12: =IF(A12="","",IFERROR(MAXIFS(WL_e1RM,WL_Exercise,A12),"")) | E12: =IF(OR(A12="",D12=""),"",IFERROR(XLOOKUP(1,(WL_Exercise=A12)*(WL_e1RM=D12),WL_Date,"",0),"")) | F12: =IF(OR(A12="",D12=""),"",IFERROR(XLOOKUP(1,(WL_Exercise=A12)*(WL_e1RM=D12),WL_Reps,"",0),"")) | G12: =IF(OR(A12="",D12=""),"",IFERROR(XLOOKUP(1,(WL_Exercise=A12)*(WL_e1RM=D12),WL_Weight,"",0),""))
A13: ='Exercise Library'!A13 | B13: =IF(A13="","",IFERROR(MAXIFS(WL_Weight,WL_Exercise,A13),"")) | C13: =IF(OR(A13="",B13=""),"",IFERROR(XLOOKUP(1,(WL_Exercise=A13)*(WL_Weight=B13),WL_Date,"",0),"")) | D13: =IF(A13="","",IFERROR(MAXIFS(WL_e1RM,WL_Exercise,A13),"")) | E13: =IF(OR(A13="",D13=""),"",IFERROR(XLOOKUP(1,(WL_Exercise=A13)*(WL_e1RM=D13),WL_Date,"",0),"")) | F13: =IF(OR(A13="",D13=""),"",IFERROR(XLOOKUP(1,(WL_Exercise=A13)*(WL_e1RM=D13),WL_Reps,"",0),"")) | G13: =IF(OR(A13="",D13=""),"",IFERROR(XLOOKUP(1,(WL_Exercise=A13)*(WL_e1RM=D13),WL_Weight,"",0),""))
... A201: ='Exercise Library'!A201 | B201: =IF(A201="","",IFERROR(MAXIFS(WL_Weight,WL_Exercise,A201),"")) | C201: =IF(OR(A201="",B201=""),"",IFERROR(XLOOKUP(1,(WL_Exercise=A201)*(WL_Weight=B201),WL_Date,"",0),"")) | D201: =IF(A201="","",IFERROR(MAXIFS(WL_e1RM,WL_Exercise,A201),"")) | E201: =IF(OR(A201="",D201=""),"",IFERROR(XLOOKUP(1,(WL_Exercise=A201)*(WL_e1RM=D201),WL_Date,"",0),"")) | F201: =IF(OR(A201="",D201=""),"",IFERROR(XLOOKUP(1,(WL_Exercise=A201)*(WL_e1RM=D201),WL_Reps,"",0),"")) | G201: =IF(OR(A201="",D201=""),"",IFERROR(XLOOKUP(1,(WL_Exercise=A201)*(WL_e1RM=D201),WL_Weight,"",0),""))

Sheet Body Measurements
A1: Date | B1: Waist | C1: Chest | D1: Arms | E1: Thighs | F1: Hips | G1: Body Fat % | H1: Notes

Sheet Dashboard
A1: Dashboard | P1: Date | Q1: Total Volume
A2: Charts pull live from Daily Log and Workout Log. Add data to see lines populate. | P2: =TODAY()-89 | Q2: =IFERROR(SUMIFS(WL_Volume,WL_Date,P2),0)
P3: =TODAY()-88 | Q3: =IFERROR(SUMIFS(WL_Volume,WL_Date,P3),0)
P4: =TODAY()-87 | Q4: =IFERROR(SUMIFS(WL_Volume,WL_Date,P4),0)
P5: =TODAY()-86 | Q5: =IFERROR(SUMIFS(WL_Volume,WL_Date,P5),0)
P6: =TODAY()-85 | Q6: =IFERROR(SUMIFS(WL_Volume,WL_Date,P6),0)
P7: =TODAY()-84 | Q7: =IFERROR(SUMIFS(WL_Volume,WL_Date,P7),0)
P8: =TODAY()-83 | Q8: =IFERROR(SUMIFS(WL_Volume,WL_Date,P8),0)
P9: =TODAY()-82 | Q9: =IFERROR(SUMIFS(WL_Volume,WL_Date,P9),0)
P10: =TODAY()-81 | Q10: =IFERROR(SUMIFS(WL_Volume,WL_Date,P10),0)
P11: =TODAY()-80 | Q11: =IFERROR(SUMIFS(WL_Volume,WL_Date,P11),0)
P12: =TODAY()-79 | Q12: =IFERROR(SUMIFS(WL_Volume,WL_Date,P12),0)
P13: =TODAY()-78 | Q13: =IFERROR(SUMIFS(WL_Volume,WL_Date,P13),0)
P14: =TODAY()-77 | Q14: =IFERROR(SUMIFS(WL_Volume,WL_Date,P14),0)
P15: =TODAY()-76 | Q15: =IFERROR(SUMIFS(WL_Volume,WL_Date,P15),0)
P16: =TODAY()-75 | Q16: =IFERROR(SUMIFS(WL_Volume,WL_Date,P16),0)
P17: =TODAY()-74 | Q17: =IFERROR(SUMIFS(WL_Volume,WL_Date,P17),0)
P18: =TODAY()-73 | Q18: =IFERROR(SUMIFS(WL_Volume,WL_Date,P18),0)
P19: =TODAY()-72 | Q19: =IFERROR(SUMIFS(WL_Volume,WL_Date,P19),0)
P20: =TODAY()-71 | Q20: =IFERROR(SUMIFS(WL_Volume,WL_Date,P20),0)
P21: =TODAY()-70 | Q21: =IFERROR(SUMIFS(WL_Volume,WL_Date,P21),0)
P22: =TODAY()-69 | Q22: =IFERROR(SUMIFS(WL_Volume,WL_Date,P22),0)
P23: =TODAY()-68 | Q23: =IFERROR(SUMIFS(WL_Volume,WL_Date,P23),0)
P24: =TODAY()-67 | Q24: =IFERROR(SUMIFS(WL_Volume,WL_Date,P24),0)
P25: =TODAY()-66 | Q25: =IFERROR(SUMIFS(WL_Volume,WL_Date,P25),0)
P26: =TODAY()-65 | Q26: =IFERROR(SUMIFS(WL_Volume,WL_Date,P26),0)
P27: =TODAY()-64 | Q27: =IFERROR(SUMIFS(WL_Volume,WL_Date,P27),0)
P28: =TODAY()-63 | Q28: =IFERROR(SUMIFS(WL_Volume,WL_Date,P28),0)
P29: =TODAY()-62 | Q29: =IFERROR(SUMIFS(WL_Volume,WL_Date,P29),0)
P30: =TODAY()-61 | Q30: =IFERROR(SUMIFS(WL_Volume,WL_Date,P30),0)
P31: =TODAY()-60 | Q31: =IFERROR(SUMIFS(WL_Volume,WL_Date,P31),0)
P32: =TODAY()-59 | Q32: =IFERROR(SUMIFS(WL_Volume,WL_Date,P32),0)
P33: =TODAY()-58 | Q33: =IFERROR(SUMIFS(WL_Volume,WL_Date,P33),0)
P34: =TODAY()-57 | Q34: =IFERROR(SUMIFS(WL_Volume,WL_Date,P34),0)
P35: =TODAY()-56 | Q35: =IFERROR(SUMIFS(WL_Volume,WL_Date,P35),0)
P36: =TODAY()-55 | Q36: =IFERROR(SUMIFS(WL_Volume,WL_Date,P36),0)
P37: =TODAY()-54 | Q37: =IFERROR(SUMIFS(WL_Volume,WL_Date,P37),0)
P38: =TODAY()-53 | Q38: =IFERROR(SUMIFS(WL_Volume,WL_Date,P38),0)
P39: =TODAY()-52 | Q39: =IFERROR(SUMIFS(WL_Volume,WL_Date,P39),0)
P40: =TODAY()-51 | Q40: =IFERROR(SUMIFS(WL_Volume,WL_Date,P40),0)
...

Sheet Exercise Lookup
A1: Pick exercise: | B1: Decline Push-Up
A3: Last performed: | B3: =IFERROR(MAXIFS(WL_Date,WL_Exercise,B1),"never")
A4: Last session: | B4: =IFERROR(TEXTJOIN(", ",TRUE,IF((WL_Exercise=B1)*(WL_Date=B3),WL_Reps&"×"&WL_Weight,"")),"")
A5: Heaviest ever: | B5: =IFERROR(MAXIFS(WL_Weight,WL_Exercise,B1),"")
A6: Best e1RM: | B6: =IFERROR(MAXIFS(WL_e1RM,WL_Exercise,B1),"")
A8: Full history (most recent first):
A9: Date | B9: Set | C9: Reps | D9: Weight | E9: RPE | F9: e1RM | G9: Notes | J9: Date | K9: Top-Set Weight | L9: Best e1RM (that day)
A10: =IFERROR(SORT(FILTER(CHOOSECOLS('Workout Log'!A2:I5001,1,3,4,5,6,9,7),WL_Exercise=B1),1,-1),"No sets logged yet for this exercise.") | J10: =IFERROR(LARGE(IF(WL_Exercise=B1,WL_Date),1),"") | K10: =IF(J10="","",IFERROR(MAXIFS(WL_Weight,WL_Exercise,B1,WL_Date,J10),"")) | L10: =IF(J10="","",IFERROR(MAXIFS(WL_e1RM,WL_Exercise,B1,WL_Date,J10),""))
J11: =IFERROR(LARGE(IF(WL_Exercise=B1,WL_Date),2),"") | K11: =IF(J11="","",IFERROR(MAXIFS(WL_Weight,WL_Exercise,B1,WL_Date,J11),"")) | L11: =IF(J11="","",IFERROR(MAXIFS(WL_e1RM,WL_Exercise,B1,WL_Date,J11),""))
J12: =IFERROR(LARGE(IF(WL_Exercise=B1,WL_Date),3),"") | K12: =IF(J12="","",IFERROR(MAXIFS(WL_Weight,WL_Exercise,B1,WL_Date,J12),"")) | L12: =IF(J12="","",IFERROR(MAXIFS(WL_e1RM,WL_Exercise,B1,WL_Date,J12),""))
J13: =IFERROR(LARGE(IF(WL_Exercise=B1,WL_Date),4),"") | K13: =IF(J13="","",IFERROR(MAXIFS(WL_Weight,WL_Exercise,B1,WL_Date,J13),"")) | L13: =IF(J13="","",IFERROR(MAXIFS(WL_e1RM,WL_Exercise,B1,WL_Date,J13),""))
J14: =IFERROR(LARGE(IF(WL_Exercise=B1,WL_Date),5),"") | K14: =IF(J14="","",IFERROR(MAXIFS(WL_Weight,WL_Exercise,B1,WL_Date,J14),"")) | L14: =IF(J14="","",IFERROR(MAXIFS(WL_e1RM,WL_Exercise,B1,WL_Date,J14),""))
J15: =IFERROR(LARGE(IF(WL_Exercise=B1,WL_Date),6),"") | K15: =IF(J15="","",IFERROR(MAXIFS(WL_Weight,WL_Exercise,B1,WL_Date,J15),"")) | L15: =IF(J15="","",IFERROR(MAXIFS(WL_e1RM,WL_Exercise,B1,WL_Date,J15),""))
J16: =IFERROR(LARGE(IF(WL_Exercise=B1,WL_Date),7),"") | K16: =IF(J16="","",IFERROR(MAXIFS(WL_Weight,WL_Exercise,B1,WL_Date,J16),"")) | L16: =IF(J16="","",IFERROR(MAXIFS(WL_e1RM,WL_Exercise,B1,WL_Date,J16),""))
J17: =IFERROR(LARGE(IF(WL_Exercise=B1,WL_Date),8),"") | K17: =IF(J17="","",IFERROR(MAXIFS(WL_Weight,WL_Exercise,B1,WL_Date,J17),"")) | L17: =IF(J17="","",IFERROR(MAXIFS(WL_e1RM,WL_Exercise,B1,WL_Date,J17),""))
J18: =IFERROR(LARGE(IF(WL_Exercise=B1,WL_Date),9),"") | K18: =IF(J18="","",IFERROR(MAXIFS(WL_Weight,WL_Exercise,B1,WL_Date,J18),"")) | L18: =IF(J18="","",IFERROR(MAXIFS(WL_e1RM,WL_Exercise,B1,WL_Date,J18),""))
J19: =IFERROR(LARGE(IF(WL_Exercise=B1,WL_Date),10),"") | K19: =IF(J19="","",IFERROR(MAXIFS(WL_Weight,WL_Exercise,B1,WL_Date,J19),"")) | L19: =IF(J19="","",IFERROR(MAXIFS(WL_e1RM,WL_Exercise,B1,WL_Date,J19),""))
J20: =IFERROR(LARGE(IF(WL_Exercise=B1,WL_Date),11),"") | K20: =IF(J20="","",IFERROR(MAXIFS(WL_Weight,WL_Exercise,B1,WL_Date,J20),"")) | L20: =IF(J20="","",IFERROR(MAXIFS(WL_e1RM,WL_Exercise,B1,WL_Date,J20),""))
J21: =IFERROR(LARGE(IF(WL_Exercise=B1,WL_Date),12),"") | K21: =IF(J21="","",IFERROR(MAXIFS(WL_Weight,WL_Exercise,B1,WL_Date,J21),"")) | L21: =IF(J21="","",IFERROR(MAXIFS(WL_e1RM,WL_Exercise,B1,WL_Date,J21),""))
J22: =IFERROR(LARGE(IF(WL_Exercise=B1,WL_Date),13),"") | K22: =IF(J22="","",IFERROR(MAXIFS(WL_Weight,WL_Exercise,B1,WL_Date,J22),"")) | L22: =IF(J22="","",IFERROR(MAXIFS(WL_e1RM,WL_Exercise,B1,WL_Date,J22),""))
J23: =IFERROR(LARGE(IF(WL_Exercise=B1,WL_Date),14),"") | K23: =IF(J23="","",IFERROR(MAXIFS(WL_Weight,WL_Exercise,B1,WL_Date,J23),"")) | L23: =IF(J23="","",IFERROR(MAXIFS(WL_e1RM,WL_Exercise,B1,WL_Date,J23),""))
J24: =IFERROR(LARGE(IF(WL_Exercise=B1,WL_Date),15),"") | K24: =IF(J24="","",IFERROR(MAXIFS(WL_Weight,WL_Exercise,B1,WL_Date,J24),"")) | L24: =IF(J24="","",IFERROR(MAXIFS(WL_e1RM,WL_Exercise,B1,WL_Date,J24),""))
J25: =IFERROR(LARGE(IF(WL_Exercise=B1,WL_Date),16),"") | K25: =IF(J25="","",IFERROR(MAXIFS(WL_Weight,WL_Exercise,B1,WL_Date,J25),"")) | L25: =IF(J25="","",IFERROR(MAXIFS(WL_e1RM,WL_Exercise,B1,WL_Date,J25),""))
J26: =IFERROR(LARGE(IF(WL_Exercise=B1,WL_Date),17),"") | K26: =IF(J26="","",IFERROR(MAXIFS(WL_Weight,WL_Exercise,B1,WL_Date,J26),"")) | L26: =IF(J26="","",IFERROR(MAXIFS(WL_e1RM,WL_Exercise,B1,WL_Date,J26),""))
J27: =IFERROR(LARGE(IF(WL_Exercise=B1,WL_Date),18),"") | K27: =IF(J27="","",IFERROR(MAXIFS(WL_Weight,WL_Exercise,B1,WL_Date,J27),"")) | L27: =IF(J27="","",IFERROR(MAXIFS(WL_e1RM,WL_Exercise,B1,WL_Date,J27),""))
J28: =IFERROR(LARGE(IF(WL_Exercise=B1,WL_Date),19),"") | K28: =IF(J28="","",IFERROR(MAXIFS(WL_Weight,WL_Exercise,B1,WL_Date,J28),"")) | L28: =IF(J28="","",IFERROR(MAXIFS(WL_e1RM,WL_Exercise,B1,WL_Date,J28),""))
J29: =IFERROR(LARGE(IF(WL_Exercise=B1,WL_Date),20),"") | K29: =IF(J29="","",IFERROR(MAXIFS(WL_Weight,WL_Exercise,B1,WL_Date,J29),"")) | L29: =IF(J29="","",IFERROR(MAXIFS(WL_e1RM,WL_Exercise,B1,WL_Date,J29),""))
J30: =IFERROR(LARGE(IF(WL_Exercise=B1,WL_Date),21),"") | K30: =IF(J30="","",IFERROR(MAXIFS(WL_Weight,WL_Exercise,B1,WL_Date,J30),"")) | L30: =IF(J30="","",IFERROR(MAXIFS(WL_e1RM,WL_Exercise,B1,WL_Date,J30),""))
J31: =IFERROR(LARGE(IF(WL_Exercise=B1,WL_Date),22),"") | K31: =IF(J31="","",IFERROR(MAXIFS(WL_Weight,WL_Exercise,B1,WL_Date,J31),"")) | L31: =IF(J31="","",IFERROR(MAXIFS(WL_e1RM,WL_Exercise,B1,WL_Date,J31),""))
J32: =IFERROR(LARGE(IF(WL_Exercise=B1,WL_Date),23),"") | K32: =IF(J32="","",IFERROR(MAXIFS(WL_Weight,WL_Exercise,B1,WL_Date,J32),"")) | L32: =IF(J32="","",IFERROR(MAXIFS(WL_e1RM,WL_Exercise,B1,WL_Date,J32),""))
J33: =IFERROR(LARGE(IF(WL_Exercise=B1,WL_Date),24),"") | K33: =IF(J33="","",IFERROR(MAXIFS(WL_Weight,WL_Exercise,B1,WL_Date,J33),"")) | L33: =IF(J33="","",IFERROR(MAXIFS(WL_e1RM,WL_Exercise,B1,WL_Date,J33),""))
J34: =IFERROR(LARGE(IF(WL_Exercise=B1,WL_Date),25),"") | K34: =IF(J34="","",IFERROR(MAXIFS(WL_Weight,WL_Exercise,B1,WL_Date,J34),"")) | L34: =IF(J34="","",IFERROR(MAXIFS(WL_e1RM,WL_Exercise,B1,WL_Date,J34),""))
J35: =IFERROR(LARGE(IF(WL_Exercise=B1,WL_Date),26),"") | K35: =IF(J35="","",IFERROR(MAXIFS(WL_Weight,WL_Exercise,B1,WL_Date,J35),"")) | L35: =IF(J35="","",IFERROR(MAXIFS(WL_e1RM,WL_Exercise,B1,WL_Date,J35),""))
J36: =IFERROR(LARGE(IF(WL_Exercise=B1,WL_Date),27),"") | K36: =IF(J36="","",IFERROR(MAXIFS(WL_Weight,WL_Exercise,B1,WL_Date,J36),"")) | L36: =IF(J36="","",IFERROR(MAXIFS(WL_e1RM,WL_Exercise,B1,WL_Date,J36),""))
J37: =IFERROR(LARGE(IF(WL_Exercise=B1,WL_Date),28),"") | K37: =IF(J37="","",IFERROR(MAXIFS(WL_Weight,WL_Exercise,B1,WL_Date,J37),"")) | L37: =IF(J37="","",IFERROR(MAXIFS(WL_e1RM,WL_Exercise,B1,WL_Date,J37),""))
J38: =IFERROR(LARGE(IF(WL_Exercise=B1,WL_Date),29),"") | K38: =IF(J38="","",IFERROR(MAXIFS(WL_Weight,WL_Exercise,B1,WL_Date,J38),"")) | L38: =IF(J38="","",IFERROR(MAXIFS(WL_e1RM,WL_Exercise,B1,WL_Date,J38),""))
J39: =IFERROR(LARGE(IF(WL_Exercise=B1,WL_Date),30),"") | K39: =IF(J39="","",IFERROR(MAXIFS(WL_Weight,WL_Exercise,B1,WL_Date,J39),"")) | L39: =IF(J39="","",IFERROR(MAXIFS(WL_e1RM,WL_Exercise,B1,WL_Date,J39),""))
J40: =IFERROR(LARGE(IF(WL_Exercise=B1,WL_Date),31),"") | K40: =IF(J40="","",IFERROR(MAXIFS(WL_Weight,WL_Exercise,B1,WL_Date,J40),"")) | L40: =IF(J40="","",IFERROR(MAXIFS(WL_e1RM,WL_Exercise,B1,WL_Date,J40),""))
J41: =IFERROR(LARGE(IF(WL_Exercise=B1,WL_Date),32),"") | K41: =IF(J41="","",IFERROR(MAXIFS(WL_Weight,WL_Exercise,B1,WL_Date,J41),"")) | L41: =IF(J41="","",IFERROR(MAXIFS(WL_e1RM,WL_Exercise,B1,WL_Date,J41),""))
J42: =IFERROR(LARGE(IF(WL_Exercise=B1,WL_Date),33),"") | K42: =IF(J42="","",IFERROR(MAXIFS(WL_Weight,WL_Exercise,B1,WL_Date,J42),"")) | L42: =IF(J42="","",IFERROR(MAXIFS(WL_e1RM,WL_Exercise,B1,WL_Date,J42),""))
...
